2024-10-27 17:27:54,533 [INFO] - fetching data for 2024-10-22-2024-10-28
2024-10-27 17:28:13,397 [ERROR] - get data
Traceback (most recent call last):
  File "C:\Users\adams\AppData\Local\Temp\ipykernel_124620\2528803132.py", line 226, in get_data
    df.columns = columns
    ^^^^^^^^^^
  File "c:\Users\adams\anaconda3\Lib\site-packages\pandas\core\generic.py", line 5500, in __setattr__
    return object.__setattr__(self, name, value)
           ^^^^^^^^^^^^^^^^^^^^^^^^^^^^^^^^^^^^^
  File "pandas\_libs\properties.pyx", line 70, in pandas._libs.properties.AxisProperty.__set__
  File "c:\Users\adams\anaconda3\Lib\site-packages\pandas\core\generic.py", line 766, in _set_axis
    self._mgr.set_axis(axis, labels)
  File "c:\Users\adams\anaconda3\Lib\site-packages\pandas\core\internals\managers.py", line 216, in set_axis
    self._validate_set_axis(axis, new_labels)
  File "c:\Users\adams\anaconda3\Lib\site-packages\pandas\core\internals\base.py", line 57, in _validate_set_axis
    raise ValueError(
ValueError: Length mismatch: Expected axis has 15 elements, new values have 11 elements
2024-10-27 17:29:54,491 [INFO] - fetching data for 2024-10-22-2024-10-28
2024-10-27 17:30:46,873 [INFO] - fetching data for 2024-10-22-2024-10-28
2024-10-27 17:33:50,763 [ERROR] - get historical data
Traceback (most recent call last):
  File "C:\Users\adams\AppData\Local\Temp\ipykernel_124620\2528803132.py", line 280, in load_historical_data
    start_date = datetime.strptime(start_date, '%Y-%m-%d')
                 ^^^^^^^^^^^^^^^^^^^^^^^^^^^^^^^^^^^^^^^^^
TypeError: strptime() argument 1 must be str, not datetime.date
